Workbook

Sheet Programme Overview
A1: Digital Programme Overview — cut-off [dd/mm/yyyy]
A3: Programme Overview
A5: Contract / initiative | B5: Delivery-system ref | C5: Lifecycle status | D5: RAG | E5: Current Step
A6: ='Delivery Overview'!A6 | B6: =IF('Delivery Overview'!B6="","",'Delivery Overview'!B6) | C6: =IF('Delivery Overview'!C6="","",'Delivery Overview'!C6) | D6: =IF('Delivery Overview'!D6="","",'Delivery Overview'!D6) | E6: =IF('Delivery Overview'!E6="","",'Delivery Overview'!E6)
A7: ='Delivery Overview'!A7 | B7: =IF('Delivery Overview'!B7="","",'Delivery Overview'!B7) | C7: =IF('Delivery Overview'!C7="","",'Delivery Overview'!C7) | D7: =IF('Delivery Overview'!D7="","",'Delivery Overview'!D7) | E7: =IF('Delivery Overview'!E7="","",'Delivery Overview'!E7)
A8: ='Delivery Overview'!A8 | B8: =IF('Delivery Overview'!B8="","",'Delivery Overview'!B8) | C8: =IF('Delivery Overview'!C8="","",'Delivery Overview'!C8) | D8: =IF('Delivery Overview'!D8="","",'Delivery Overview'!D8) | E8: =IF('Delivery Overview'!E8="","",'Delivery Overview'!E8)
A9: ='Delivery Overview'!A9 | B9: =IF('Delivery Overview'!B9="","",'Delivery Overview'!B9) | C9: =IF('Delivery Overview'!C9="","",'Delivery Overview'!C9) | D9: =IF('Delivery Overview'!D9="","",'Delivery Overview'!D9) | E9: =IF('Delivery Overview'!E9="","",'Delivery Overview'!E9)
A10: ='Delivery Overview'!A10 | B10: =IF('Delivery Overview'!B10="","",'Delivery Overview'!B10) | C10: =IF('Delivery Overview'!C10="","",'Delivery Overview'!C10) | D10: =IF('Delivery Overview'!D10="","",'Delivery Overview'!D10) | E10: =IF('Delivery Overview'!E10="","",'Delivery Overview'!E10)
A11: ='Delivery Overview'!A11 | B11: =IF('Delivery Overview'!B11="","",'Delivery Overview'!B11) | C11: =IF('Delivery Overview'!C11="","",'Delivery Overview'!C11) | D11: =IF('Delivery Overview'!D11="","",'Delivery Overview'!D11) | E11: =IF('Delivery Overview'!E11="","",'Delivery Overview'!E11)
A12: ='Delivery Overview'!A12 | B12: =IF('Delivery Overview'!B12="","",'Delivery Overview'!B12) | C12: =IF('Delivery Overview'!C12="","",'Delivery Overview'!C12) | D12: =IF('Delivery Overview'!D12="","",'Delivery Overview'!D12) | E12: =IF('Delivery Overview'!E12="","",'Delivery Overview'!E12)
A13: ='Delivery Overview'!A13 | B13: =IF('Delivery Overview'!B13="","",'Delivery Overview'!B13) | C13: =IF('Delivery Overview'!C13="","",'Delivery Overview'!C13) | D13: =IF('Delivery Overview'!D13="","",'Delivery Overview'!D13) | E13: =IF('Delivery Overview'!E13="","",'Delivery Overview'!E13)
A14: ='Delivery Overview'!A14 | B14: =IF('Delivery Overview'!B14="","",'Delivery Overview'!B14) | C14: =IF('Delivery Overview'!C14="","",'Delivery Overview'!C14) | D14: =IF('Delivery Overview'!D14="","",'Delivery Overview'!D14) | E14: =IF('Delivery Overview'!E14="","",'Delivery Overview'!E14)
A15: ='Delivery Overview'!A15 | B15: =IF('Delivery Overview'!B15="","",'Delivery Overview'!B15) | C15: =IF('Delivery Overview'!C15="","",'Delivery Overview'!C15) | D15: =IF('Delivery Overview'!D15="","",'Delivery Overview'!D15) | E15: =IF('Delivery Overview'!E15="","",'Delivery Overview'!E15)
A16: ='Delivery Overview'!A16 | B16: =IF('Delivery Overview'!B16="","",'Delivery Overview'!B16) | C16: =IF('Delivery Overview'!C16="","",'Delivery Overview'!C16) | D16: =IF('Delivery Overview'!D16="","",'Delivery Overview'!D16) | E16: =IF('Delivery Overview'!E16="","",'Delivery Overview'!E16)
A17: ='Delivery Overview'!A17 | B17: =IF('Delivery Overview'!B17="","",'Delivery Overview'!B17) | C17: =IF('Delivery Overview'!C17="","",'Delivery Overview'!C17) | D17: =IF('Delivery Overview'!D17="","",'Delivery Overview'!D17) | E17: =IF('Delivery Overview'!E17="","",'Delivery Overview'!E17)
... A25: ='Delivery Overview'!A25 | B25: =IF('Delivery Overview'!B25="","",'Delivery Overview'!B25) | C25: =IF('Delivery Overview'!C25="","",'Delivery Overview'!C25) | D25: =IF('Delivery Overview'!D25="","",'Delivery Overview'!D25) | E25: =IF('Delivery Overview'!E25="","",'Delivery Overview'!E25)

Sheet Delivery Overview
A1: Digital Programme Overview — cut-off [dd/mm/yyyy]
A3: Delivery Overview
A5: Contract / initiative | B5: Delivery-system ref | C5: Lifecycle status | D5: RAG | E5: Current Step | F5: Leadership Approval | G5: Vendor Onboarded | H5: Project kick-off | I5: PEP Build | J5: Work Delivered | K5: Functional Testing | L5: UAT approval | M5: Go-live | N5: Hypercare | O5: Adoption (30-day) | P5: Actions (Open) | Q5: Actions (Overdue) | R5: RAID (Open) | S5: Notes
A6: Contract A | E6: =COUNTA(A7:A10)&IF(COUNTA(A7:A10)=1," initiative"," initiatives")
E7: =IF(A7="","",IF(COUNTIF(F7:O7,"● Blocked")>0,"Blocked: "&INDEX($F$5:$O$5,MATCH("● Blocked",F7:O7,0)),IF(COUNTIF(F7:O7,"● In Progress")>0,"In Progress: "&INDEX($F$5:$O$5,MATCH("● In Progress",F7:O7,0)),IF((COUNTIF(F7:O7,"● Complete")+COUNTIF(F7:O7,"● Not required"))=10,"All steps complete",IF(COUNTA(F7:O7)=0,"Not started","Next: "&INDEX($F$5:$O$5,MATCH(TRUE,INDEX((F7:O7<>"● Complete")*(F7:O7<>"● Not required"),0),0))))))) | P7: =IF(A7="","",COUNTIF(Actions!$E$27:$E$46,"Open")+COUNTIF(Actions!$E$27:$E$46,"In progress")+COUNTIF(Actions!$E$27:$E$46,"Blocked")) | Q7: =IF(A7="","",COUNTIF(Actions!$G$27:$G$46,"Overdue")) | R7: =IF(A7="","",COUNTIFS(RAID!$C:$C,A7,RAID!$H:$H,"Open")+COUNTIFS(RAID!$C:$C,A7,RAID!$H:$H,"In progress")+COUNTIFS(RAID!$C:$C,A7,RAID!$H:$H,"Blocked"))
E8: =IF(A8="","",IF(COUNTIF(F8:O8,"● Blocked")>0,"Blocked: "&INDEX($F$5:$O$5,MATCH("● Blocked",F8:O8,0)),IF(COUNTIF(F8:O8,"● In Progress")>0,"In Progress: "&INDEX($F$5:$O$5,MATCH("● In Progress",F8:O8,0)),IF((COUNTIF(F8:O8,"● Complete")+COUNTIF(F8:O8,"● Not required"))=10,"All steps complete",IF(COUNTA(F8:O8)=0,"Not started","Next: "&INDEX($F$5:$O$5,MATCH(TRUE,INDEX((F8:O8<>"● Complete")*(F8:O8<>"● Not required"),0),0))))))) | P8: =IF(A8="","",COUNTIF(Actions!$E$48:$E$67,"Open")+COUNTIF(Actions!$E$48:$E$67,"In progress")+COUNTIF(Actions!$E$48:$E$67,"Blocked")) | Q8: =IF(A8="","",COUNTIF(Actions!$G$48:$G$67,"Overdue")) | R8: =IF(A8="","",COUNTIFS(RAID!$C:$C,A8,RAID!$H:$H,"Open")+COUNTIFS(RAID!$C:$C,A8,RAID!$H:$H,"In progress")+COUNTIFS(RAID!$C:$C,A8,RAID!$H:$H,"Blocked"))
E9: =IF(A9="","",IF(COUNTIF(F9:O9,"● Blocked")>0,"Blocked: "&INDEX($F$5:$O$5,MATCH("● Blocked",F9:O9,0)),IF(COUNTIF(F9:O9,"● In Progress")>0,"In Progress: "&INDEX($F$5:$O$5,MATCH("● In Progress",F9:O9,0)),IF((COUNTIF(F9:O9,"● Complete")+COUNTIF(F9:O9,"● Not required"))=10,"All steps complete",IF(COUNTA(F9:O9)=0,"Not started","Next: "&INDEX($F$5:$O$5,MATCH(TRUE,INDEX((F9:O9<>"● Complete")*(F9:O9<>"● Not required"),0),0))))))) | P9: =IF(A9="","",COUNTIF(Actions!$E$69:$E$88,"Open")+COUNTIF(Actions!$E$69:$E$88,"In progress")+COUNTIF(Actions!$E$69:$E$88,"Blocked")) | Q9: =IF(A9="","",COUNTIF(Actions!$G$69:$G$88,"Overdue")) | R9: =IF(A9="","",COUNTIFS(RAID!$C:$C,A9,RAID!$H:$H,"Open")+COUNTIFS(RAID!$C:$C,A9,RAID!$H:$H,"In progress")+COUNTIFS(RAID!$C:$C,A9,RAID!$H:$H,"Blocked"))
E10: =IF(A10="","",IF(COUNTIF(F10:O10,"● Blocked")>0,"Blocked: "&INDEX($F$5:$O$5,MATCH("● Blocked",F10:O10,0)),IF(COUNTIF(F10:O10,"● In Progress")>0,"In Progress: "&INDEX($F$5:$O$5,MATCH("● In Progress",F10:O10,0)),IF((COUNTIF(F10:O10,"● Complete")+COUNTIF(F10:O10,"● Not required"))=10,"All steps complete",IF(COUNTA(F10:O10)=0,"Not started","Next: "&INDEX($F$5:$O$5,MATCH(TRUE,INDEX((F10:O10<>"● Complete")*(F10:O10<>"● Not required"),0),0))))))) | P10: =IF(A10="","",COUNTIF(Actions!$E$90:$E$109,"Open")+COUNTIF(Actions!$E$90:$E$109,"In progress")+COUNTIF(Actions!$E$90:$E$109,"Blocked")) | Q10: =IF(A10="","",COUNTIF(Actions!$G$90:$G$109,"Overdue")) | R10: =IF(A10="","",COUNTIFS(RAID!$C:$C,A10,RAID!$H:$H,"Open")+COUNTIFS(RAID!$C:$C,A10,RAID!$H:$H,"In progress")+COUNTIFS(RAID!$C:$C,A10,RAID!$H:$H,"Blocked"))
A11: Contract B | E11: =COUNTA(A12:A15)&IF(COUNTA(A12:A15)=1," initiative"," initiatives")
E12: =IF(A12="","",IF(COUNTIF(F12:O12,"● Blocked")>0,"Blocked: "&INDEX($F$5:$O$5,MATCH("● Blocked",F12:O12,0)),IF(COUNTIF(F12:O12,"● In Progress")>0,"In Progress: "&INDEX($F$5:$O$5,MATCH("● In Progress",F12:O12,0)),IF((COUNTIF(F12:O12,"● Complete")+COUNTIF(F12:O12,"● Not required"))=10,"All steps complete",IF(COUNTA(F12:O12)=0,"Not started","Next: "&INDEX($F$5:$O$5,MATCH(TRUE,INDEX((F12:O12<>"● Complete")*(F12:O12<>"● Not required"),0),0))))))) | P12: =IF(A12="","",COUNTIF(Actions!$E$154:$E$173,"Open")+COUNTIF(Actions!$E$154:$E$173,"In progress")+COUNTIF(Actions!$E$154:$E$173,"Blocked")) | Q12: =IF(A12="","",COUNTIF(Actions!$G$154:$G$173,"Overdue")) | R12: =IF(A12="","",COUNTIFS(RAID!$C:$C,A12,RAID!$H:$H,"Open")+COUNTIFS(RAID!$C:$C,A12,RAID!$H:$H,"In progress")+COUNTIFS(RAID!$C:$C,A12,RAID!$H:$H,"Blocked"))
E13: =IF(A13="","",IF(COUNTIF(F13:O13,"● Blocked")>0,"Blocked: "&INDEX($F$5:$O$5,MATCH("● Blocked",F13:O13,0)),IF(COUNTIF(F13:O13,"● In Progress")>0,"In Progress: "&INDEX($F$5:$O$5,MATCH("● In Progress",F13:O13,0)),IF((COUNTIF(F13:O13,"● Complete")+COUNTIF(F13:O13,"● Not required"))=10,"All steps complete",IF(COUNTA(F13:O13)=0,"Not started","Next: "&INDEX($F$5:$O$5,MATCH(TRUE,INDEX((F13:O13<>"● Complete")*(F13:O13<>"● Not required"),0),0))))))) | P13: =IF(A13="","",COUNTIF(Actions!$E$175:$E$194,"Open")+COUNTIF(Actions!$E$175:$E$194,"In progress")+COUNTIF(Actions!$E$175:$E$194,"Blocked")) | Q13: =IF(A13="","",COUNTIF(Actions!$G$175:$G$194,"Overdue")) | R13: =IF(A13="","",COUNTIFS(RAID!$C:$C,A13,RAID!$H:$H,"Open")+COUNTIFS(RAID!$C:$C,A13,RAID!$H:$H,"In progress")+COUNTIFS(RAID!$C:$C,A13,RAID!$H:$H,"Blocked"))
E14: =IF(A14="","",IF(COUNTIF(F14:O14,"● Blocked")>0,"Blocked: "&INDEX($F$5:$O$5,MATCH("● Blocked",F14:O14,0)),IF(COUNTIF(F14:O14,"● In Progress")>0,"In Progress: "&INDEX($F$5:$O$5,MATCH("● In Progress",F14:O14,0)),IF((COUNTIF(F14:O14,"● Complete")+COUNTIF(F14:O14,"● Not required"))=10,"All steps complete",IF(COUNTA(F14:O14)=0,"Not started","Next: "&INDEX($F$5:$O$5,MATCH(TRUE,INDEX((F14:O14<>"● Complete")*(F14:O14<>"● Not required"),0),0))))))) | P14: =IF(A14="","",COUNTIF(Actions!$E$196:$E$215,"Open")+COUNTIF(Actions!$E$196:$E$215,"In progress")+COUNTIF(Actions!$E$196:$E$215,"Blocked")) | Q14: =IF(A14="","",COUNTIF(Actions!$G$196:$G$215,"Overdue")) | R14: =IF(A14="","",COUNTIFS(RAID!$C:$C,A14,RAID!$H:$H,"Open")+COUNTIFS(RAID!$C:$C,A14,RAID!$H:$H,"In progress")+COUNTIFS(RAID!$C:$C,A14,RAID!$H:$H,"Blocked"))
E15: =IF(A15="","",IF(COUNTIF(F15:O15,"● Blocked")>0,"Blocked: "&INDEX($F$5:$O$5,MATCH("● Blocked",F15:O15,0)),IF(COUNTIF(F15:O15,"● In Progress")>0,"In Progress: "&INDEX($F$5:$O$5,MATCH("● In Progress",F15:O15,0)),IF((COUNTIF(F15:O15,"● Complete")+COUNTIF(F15:O15,"● Not required"))=10,"All steps complete",IF(COUNTA(F15:O15)=0,"Not started","Next: "&INDEX($F$5:$O$5,MATCH(TRUE,INDEX((F15:O15<>"● Complete")*(F15:O15<>"● Not required"),0),0))))))) | P15: =IF(A15="","",COUNTIF(Actions!$E$217:$E$236,"Open")+COUNTIF(Actions!$E$217:$E$236,"In progress")+COUNTIF(Actions!$E$217:$E$236,"Blocked")) | Q15: =IF(A15="","",COUNTIF(Actions!$G$217:$G$236,"Overdue")) | R15: =IF(A15="","",COUNTIFS(RAID!$C:$C,A15,RAID!$H:$H,"Open")+COUNTIFS(RAID!$C:$C,A15,RAID!$H:$H,"In progress")+COUNTIFS(RAID!$C:$C,A15,RAID!$H:$H,"Blocked"))
A16: Contract C | E16: =COUNTA(A17:A20)&IF(COUNTA(A17:A20)=1," initiative"," initiatives")
E17: =IF(A17="","",IF(COUNTIF(F17:O17,"● Blocked")>0,"Blocked: "&INDEX($F$5:$O$5,MATCH("● Blocked",F17:O17,0)),IF(COUNTIF(F17:O17,"● In Progress")>0,"In Progress: "&INDEX($F$5:$O$5,MATCH("● In Progress",F17:O17,0)),IF((COUNTIF(F17:O17,"● Complete")+COUNTIF(F17:O17,"● Not required"))=10,"All steps complete",IF(COUNTA(F17:O17)=0,"Not started","Next: "&INDEX($F$5:$O$5,MATCH(TRUE,INDEX((F17:O17<>"● Complete")*(F17:O17<>"● Not required"),0),0))))))) | P17: =IF(A17="","",COUNTIF(Actions!$E$281:$E$300,"Open")+COUNTIF(Actions!$E$281:$E$300,"In progress")+COUNTIF(Actions!$E$281:$E$300,"Blocked")) | Q17: =IF(A17="","",COUNTIF(Actions!$G$281:$G$300,"Overdue")) | R17: =IF(A17="","",COUNTIFS(RAID!$C:$C,A17,RAID!$H:$H,"Open")+COUNTIFS(RAID!$C:$C,A17,RAID!$H:$H,"In progress")+COUNTIFS(RAID!$C:$C,A17,RAID!$H:$H,"Blocked"))
E18: =IF(A18="","",IF(COUNTIF(F18:O18,"● Blocked")>0,"Blocked: "&INDEX($F$5:$O$5,MATCH("● Blocked",F18:O18,0)),IF(COUNTIF(F18:O18,"● In Progress")>0,"In Progress: "&INDEX($F$5:$O$5,MATCH("● In Progress",F18:O18,0)),IF((COUNTIF(F18:O18,"● Complete")+COUNTIF(F18:O18,"● Not required"))=10,"All steps complete",IF(COUNTA(F18:O18)=0,"Not started","Next: "&INDEX($F$5:$O$5,MATCH(TRUE,INDEX((F18:O18<>"● Complete")*(F18:O18<>"● Not required"),0),0))))))) | P18: =IF(A18="","",COUNTIF(Actions!$E$302:$E$321,"Open")+COUNTIF(Actions!$E$302:$E$321,"In progress")+COUNTIF(Actions!$E$302:$E$321,"Blocked")) | Q18: =IF(A18="","",COUNTIF(Actions!$G$302:$G$321,"Overdue")) | R18: =IF(A18="","",COUNTIFS(RAID!$C:$C,A18,RAID!$H:$H,"Open")+COUNTIFS(RAID!$C:$C,A18,RAID!$H:$H,"In progress")+COUNTIFS(RAID!$C:$C,A18,RAID!$H:$H,"Blocked"))
E19: =IF(A19="","",IF(COUNTIF(F19:O19,"● Blocked")>0,"Blocked: "&INDEX($F$5:$O$5,MATCH("● Blocked",F19:O19,0)),IF(COUNTIF(F19:O19,"● In Progress")>0,"In Progress: "&INDEX($F$5:$O$5,MATCH("● In Progress",F19:O19,0)),IF((COUNTIF(F19:O19,"● Complete")+COUNTIF(F19:O19,"● Not required"))=10,"All steps complete",IF(COUNTA(F19:O19)=0,"Not started","Next: "&INDEX($F$5:$O$5,MATCH(TRUE,INDEX((F19:O19<>"● Complete")*(F19:O19<>"● Not required"),0),0))))))) | P19: =IF(A19="","",COUNTIF(Actions!$E$323:$E$342,"Open")+COUNTIF(Actions!$E$323:$E$342,"In progress")+COUNTIF(Actions!$E$323:$E$342,"Blocked")) | Q19: =IF(A19="","",COUNTIF(Actions!$G$323:$G$342,"Overdue")) | R19: =IF(A19="","",COUNTIFS(RAID!$C:$C,A19,RAID!$H:$H,"Open")+COUNTIFS(RAID!$C:$C,A19,RAID!$H:$H,"In progress")+COUNTIFS(RAID!$C:$C,A19,RAID!$H:$H,"Blocked"))
E20: =IF(A20="","",IF(COUNTIF(F20:O20,"● Blocked")>0,"Blocked: "&INDEX($F$5:$O$5,MATCH("● Blocked",F20:O20,0)),IF(COUNTIF(F20:O20,"● In Progress")>0,"In Progress: "&INDEX($F$5:$O$5,MATCH("● In Progress",F20:O20,0)),IF((COUNTIF(F20:O20,"● Complete")+COUNTIF(F20:O20,"● Not required"))=10,"All steps complete",IF(COUNTA(F20:O20)=0,"Not started","Next: "&INDEX($F$5:$O$5,MATCH(TRUE,INDEX((F20:O20<>"● Complete")*(F20:O20<>"● Not required"),0),0))))))) | P20: =IF(A20="","",COUNTIF(Actions!$E$344:$E$363,"Open")+COUNTIF(Actions!$E$344:$E$363,"In progress")+COUNTIF(Actions!$E$344:$E$363,"Blocked")) | Q20: =IF(A20="","",COUNTIF(Actions!$G$344:$G$363,"Overdue")) | R20: =IF(A20="","",COUNTIFS(RAID!$C:$C,A20,RAID!$H:$H,"Open")+COUNTIFS(RAID!$C:$C,A20,RAID!$H:$H,"In progress")+COUNTIFS(RAID!$C:$C,A20,RAID!$H:$H,"Blocked"))
A21: Programme-level (no contract) | E21: =COUNTA(A22:A25)&IF(COUNTA(A22:A25)=1," initiative"," initiatives")
E22: =IF(A22="","",IF(COUNTIF(F22:O22,"● Blocked")>0,"Blocked: "&INDEX($F$5:$O$5,MATCH("● Blocked",F22:O22,0)),IF(COUNTIF(F22:O22,"● In Progress")>0,"In Progress: "&INDEX($F$5:$O$5,MATCH("● In Progress",F22:O22,0)),IF((COUNTIF(F22:O22,"● Complete")+COUNTIF(F22:O22,"● Not required"))=10,"All steps complete",IF(COUNTA(F22:O22)=0,"Not started","Next: "&INDEX($F$5:$O$5,MATCH(TRUE,INDEX((F22:O22<>"● Complete")*(F22:O22<>"● Not required"),0),0))))))) | P22: =IF(A22="","",COUNTIF(Actions!$E$408:$E$427,"Open")+COUNTIF(Actions!$E$408:$E$427,"In progress")+COUNTIF(Actions!$E$408:$E$427,"Blocked")) | Q22: =IF(A22="","",COUNTIF(Actions!$G$408:$G$427,"Overdue")) | R22: =IF(A22="","",COUNTIFS(RAID!$C:$C,A22,RAID!$H:$H,"Open")+COUNTIFS(RAID!$C:$C,A22,RAID!$H:$H,"In progress")+COUNTIFS(RAID!$C:$C,A22,RAID!$H:$H,"Blocked"))
E23: =IF(A23="","",IF(COUNTIF(F23:O23,"● Blocked")>0,"Blocked: "&INDEX($F$5:$O$5,MATCH("● Blocked",F23:O23,0)),IF(COUNTIF(F23:O23,"● In Progress")>0,"In Progress: "&INDEX($F$5:$O$5,MATCH("● In Progress",F23:O23,0)),IF((COUNTIF(F23:O23,"● Complete")+COUNTIF(F23:O23,"● Not required"))=10,"All steps complete",IF(COUNTA(F23:O23)=0,"Not started","Next: "&INDEX($F$5:$O$5,MATCH(TRUE,INDEX((F23:O23<>"● Complete")*(F23:O23<>"● Not required"),0),0))))))) | P23: =IF(A23="","",COUNTIF(Actions!$E$429:$E$448,"Open")+COUNTIF(Actions!$E$429:$E$448,"In progress")+COUNTIF(Actions!$E$429:$E$448,"Blocked")) | Q23: =IF(A23="","",COUNTIF(Actions!$G$429:$G$448,"Overdue")) | R23: =IF(A23="","",COUNTIFS(RAID!$C:$C,A23,RAID!$H:$H,"Open")+COUNTIFS(RAID!$C:$C,A23,RAID!$H:$H,"In progress")+COUNTIFS(RAID!$C:$C,A23,RAID!$H:$H,"Blocked"))
E24: =IF(A24="","",IF(COUNTIF(F24:O24,"● Blocked")>0,"Blocked: "&INDEX($F$5:$O$5,MATCH("● Blocked",F24:O24,0)),IF(COUNTIF(F24:O24,"● In Progress")>0,"In Progress: "&INDEX($F$5:$O$5,MATCH("● In Progress",F24:O24,0)),IF((COUNTIF(F24:O24,"● Complete")+COUNTIF(F24:O24,"● Not required"))=10,"All steps complete",IF(COUNTA(F24:O24)=0,"Not started","Next: "&INDEX($F$5:$O$5,MATCH(TRUE,INDEX((F24:O24<>"● Complete")*(F24:O24<>"● Not required"),0),0))))))) | P24: =IF(A24="","",COUNTIF(Actions!$E$450:$E$469,"Open")+COUNTIF(Actions!$E$450:$E$469,"In progress")+COUNTIF(Actions!$E$450:$E$469,"Blocked")) | Q24: =IF(A24="","",COUNTIF(Actions!$G$450:$G$469,"Overdue")) | R24: =IF(A24="","",COUNTIFS(RAID!$C:$C,A24,RAID!$H:$H,"Open")+COUNTIFS(RAID!$C:$C,A24,RAID!$H:$H,"In progress")+COUNTIFS(RAID!$C:$C,A24,RAID!$H:$H,"Blocked"))
E25: =IF(A25="","",IF(COUNTIF(F25:O25,"● Blocked")>0,"Blocked: "&INDEX($F$5:$O$5,MATCH("● Blocked",F25:O25,0)),IF(COUNTIF(F25:O25,"● In Progress")>0,"In Progress: "&INDEX($F$5:$O$5,MATCH("● In Progress",F25:O25,0)),IF((COUNTIF(F25:O25,"● Complete")+COUNTIF(F25:O25,"● Not required"))=10,"All steps complete",IF(COUNTA(F25:O25)=0,"Not started","Next: "&INDEX($F$5:$O$5,MATCH(TRUE,INDEX((F25:O25<>"● Complete")*(F25:O25<>"● Not required"),0),0))))))) | P25: =IF(A25="","",COUNTIF(Actions!$E$471:$E$490,"Open")+COUNTIF(Actions!$E$471:$E$490,"In progress")+COUNTIF(Actions!$E$471:$E$490,"Blocked")) | Q25: =IF(A25="","",COUNTIF(Actions!$G$471:$G$490,"Overdue")) | R25: =IF(A25="","",COUNTIFS(RAID!$C:$C,A25,RAID!$H:$H,"Open")+COUNTIFS(RAID!$C:$C,A25,RAID!$H:$H,"In progress")+COUNTIFS(RAID!$C:$C,A25,RAID!$H:$H,"Blocked"))

Sheet Actions
A1: Action Tracker
A3: Action ID | B3: Action | C3: Owner | D3: Due | E3: Status | F3: Notes | G3: Overdue
A4: ="Contract A — "&(COUNTIF($E$4:$E$130,"Open")+COUNTIF($E$4:$E$130,"In progress")+COUNTIF($E$4:$E$130,"Blocked"))&" open · "&COUNTIF($G$4:$G$130,"Overdue")&" overdue"
A5: ="Contract A · Contract-level — "&(COUNTIF($E$6:$E$25,"Open")+COUNTIF($E$6:$E$25,"In progress")+COUNTIF($E$6:$E$25,"Blocked"))&" open · "&COUNTIF($G$6:$G$25,"Overdue")&" overdue"
G6: =IF(AND(B6<>"",D6<>"",OR(E6="Open",E6="In progress",E6="Blocked")),IF(D6<TODAY(),"Overdue",""),"")
G7: =IF(AND(B7<>"",D7<>"",OR(E7="Open",E7="In progress",E7="Blocked")),IF(D7<TODAY(),"Overdue",""),"")
G8: =IF(AND(B8<>"",D8<>"",OR(E8="Open",E8="In progress",E8="Blocked")),IF(D8<TODAY(),"Overdue",""),"")
G9: =IF(AND(B9<>"",D9<>"",OR(E9="Open",E9="In progress",E9="Blocked")),IF(D9<TODAY(),"Overdue",""),"")
G10: =IF(AND(B10<>"",D10<>"",OR(E10="Open",E10="In progress",E10="Blocked")),IF(D10<TODAY(),"Overdue",""),"")
G11: =IF(AND(B11<>"",D11<>"",OR(E11="Open",E11="In progress",E11="Blocked")),IF(D11<TODAY(),"Overdue",""),"")
G12: =IF(AND(B12<>"",D12<>"",OR(E12="Open",E12="In progress",E12="Blocked")),IF(D12<TODAY(),"Overdue",""),"")
G13: =IF(AND(B13<>"",D13<>"",OR(E13="Open",E13="In progress",E13="Blocked")),IF(D13<TODAY(),"Overdue",""),"")
G14: =IF(AND(B14<>"",D14<>"",OR(E14="Open",E14="In progress",E14="Blocked")),IF(D14<TODAY(),"Overdue",""),"")
G15: =IF(AND(B15<>"",D15<>"",OR(E15="Open",E15="In progress",E15="Blocked")),IF(D15<TODAY(),"Overdue",""),"")
G16: =IF(AND(B16<>"",D16<>"",OR(E16="Open",E16="In progress",E16="Blocked")),IF(D16<TODAY(),"Overdue",""),"")
G17: =IF(AND(B17<>"",D17<>"",OR(E17="Open",E17="In progress",E17="Blocked")),IF(D17<TODAY(),"Overdue",""),"")
... G25: =IF(AND(B25<>"",D25<>"",OR(E25="Open",E25="In progress",E25="Blocked")),IF(D25<TODAY(),"Overdue",""),"")
A26: ="Contract A · Initiative 1 — "&(COUNTIF($E$27:$E$46,"Open")+COUNTIF($E$27:$E$46,"In progress")+COUNTIF($E$27:$E$46,"Blocked"))&" open · "&COUNTIF($G$27:$G$46,"Overdue")&" overdue"
G27: =IF(AND(B27<>"",D27<>"",OR(E27="Open",E27="In progress",E27="Blocked")),IF(D27<TODAY(),"Overdue",""),"")
G28: =IF(AND(B28<>"",D28<>"",OR(E28="Open",E28="In progress",E28="Blocked")),IF(D28<TODAY(),"Overdue",""),"")
G29: =IF(AND(B29<>"",D29<>"",OR(E29="Open",E29="In progress",E29="Blocked")),IF(D29<TODAY(),"Overdue",""),"")
G30: =IF(AND(B30<>"",D30<>"",OR(E30="Open",E30="In progress",E30="Blocked")),IF(D30<TODAY(),"Overdue",""),"")
G31: =IF(AND(B31<>"",D31<>"",OR(E31="Open",E31="In progress",E31="Blocked")),IF(D31<TODAY(),"Overdue",""),"")
G32: =IF(AND(B32<>"",D32<>"",OR(E32="Open",E32="In progress",E32="Blocked")),IF(D32<TODAY(),"Overdue",""),"")
G33: =IF(AND(B33<>"",D33<>"",OR(E33="Open",E33="In progress",E33="Blocked")),IF(D33<TODAY(),"Overdue",""),"")
G34: =IF(AND(B34<>"",D34<>"",OR(E34="Open",E34="In progress",E34="Blocked")),IF(D34<TODAY(),"Overdue",""),"")
G35: =IF(AND(B35<>"",D35<>"",OR(E35="Open",E35="In progress",E35="Blocked")),IF(D35<TODAY(),"Overdue",""),"")
G36: =IF(AND(B36<>"",D36<>"",OR(E36="Open",E36="In progress",E36="Blocked")),IF(D36<TODAY(),"Overdue",""),"")
G37: =IF(AND(B37<>"",D37<>"",OR(E37="Open",E37="In progress",E37="Blocked")),IF(D37<TODAY(),"Overdue",""),"")
G38: =IF(AND(B38<>"",D38<>"",OR(E38="Open",E38="In progress",E38="Blocked")),IF(D38<TODAY(),"Overdue",""),"")
... G46: =IF(AND(B46<>"",D46<>"",OR(E46="Open",E46="In progress",E46="Blocked")),IF(D46<TODAY(),"Overdue",""),"")
A47: ="Contract A · Initiative 2 — "&(COUNTIF($E$48:$E$67,"Open")+COUNTIF($E$48:$E$67,"In progress")+COUNTIF($E$48:$E$67,"Blocked"))&" open · "&COUNTIF($G$48:$G$67,"Overdue")&" overdue"
G48: =IF(AND(B48<>"",D48<>"",OR(E48="Open",E48="In progress",E48="Blocked")),IF(D48<TODAY(),"Overdue",""),"")
G49: =IF(AND(B49<>"",D49<>"",OR(E49="Open",E49="In progress",E49="Blocked")),IF(D49<TODAY(),"Overdue",""),"")
G50: =IF(AND(B50<>"",D50<>"",OR(E50="Open",E50="In progress",E50="Blocked")),IF(D50<TODAY(),"Overdue",""),"")
G51: =IF(AND(B51<>"",D51<>"",OR(E51="Open",E51="In progress",E51="Blocked")),IF(D51<TODAY(),"Overdue",""),"")
G52: =IF(AND(B52<>"",D52<>"",OR(E52="Open",E52="In progress",E52="Blocked")),IF(D52<TODAY(),"Overdue",""),"")
G53: =IF(AND(B53<>"",D53<>"",OR(E53="Open",E53="In progress",E53="Blocked")),IF(D53<TODAY(),"Overdue",""),"")
G54: =IF(AND(B54<>"",D54<>"",OR(E54="Open",E54="In progress",E54="Blocked")),IF(D54<TODAY(),"Overdue",""),"")
G55: =IF(AND(B55<>"",D55<>"",OR(E55="Open",E55="In progress",E55="Blocked")),IF(D55<TODAY(),"Overdue",""),"")
...

Sheet RAID
A1: RAID Register
A3: RAID ID | B3: Type | C3: Initiative | D3: Description | E3: Owner | F3: Raised | G3: Priority | H3: Status | I3: Due / review | J3: Notes

Sheet Lists
A1: Step state | B1: Lifecycle status | C1: RAG | D1: Action status | E1: RAID type | F1: RAID priority
A2: ● Complete | B2: ● Hopper Backlog | C2: Green | D2: Open | E2: Risk | F2: Critical
A3: ● In Progress | B3: ● Initiation Form in Progress | C3: Amber | D3: In progress | E3: Assumption | F3: High
A4: ● Not started | B4: ● Mobilising | C4: Red | D4: Blocked | E4: Issue | F4: Medium
A5: ● Not required | B5: ● In Delivery | D5: Done | E5: Dependency | F5: Low
A6: ● Blocked | B6: ● Operational / Live | D6: Cancelled
B7: ● Closed / Retired
B8: ● Paused (On Hold)
